Workbook

Sheet Bricks
A1: S.No | B1: Date | C1: Day | D1: No Of Week | E1: Name | F1: Brick | G1: Line | H1: Total Brick | I1: Round Total Brick | J1: Amount of pre brick | K1: Total Amount
A2: =ROW()-1 -> 1 | B2: 45566 | C2: =TEXT(KDK[[#This Row],[Date]],"dddd") -> Tuesday | D2: =WEEKNUM(KDK[[#This Row],[Date]],2) -> 40 | E2: Aakash | F2: 25 | G2: 42 | H2: =KDK[[#This Row],[Brick]]*KDK[[#This Row],[Line]] -> 1050 | I2: =IF(MOD(KDK[[#This Row],[Total Brick]],100)>90,KDK[[#This Row],[Total Brick]] - MOD(KDK[[#This Row],[Total Brick]],100) + 100,IF(MOD(KDK[[#This Row],[Total Brick]],100)>40,KDK[[#This Row],[Total Brick]] - MOD(KDK[[#This Row],[Total Brick]],100)+50,KDK[[#This Row],[Total Brick]] - MOD(KDK[[#This Row],[Total Brick]],100))) -> 1050 | J2: =_xlfn.IFNA(1.5,0) -> 1.5 | K2: =KDK[[#This Row],[Round Total Brick]]*KDK[[#This Row],[Amount of pre brick]] -> 1575
A3: =ROW()-1 -> 2 | B3: 45566 | C3: =TEXT(KDK[[#This Row],[Date]],"dddd") -> Tuesday | D3: =WEEKNUM(KDK[[#This Row],[Date]],2) -> 40 | E3: Mahesh | F3: =_xlfn.IFNA(0,"") -> 0 | G3: =_xlfn.IFNA(0,"") -> 0 | H3: =KDK[[#This Row],[Brick]]*KDK[[#This Row],[Line]] -> 0 | I3: =IF(MOD(KDK[[#This Row],[Total Brick]],100)>90,KDK[[#This Row],[Total Brick]] - MOD(KDK[[#This Row],[Total Brick]],100) + 100,IF(MOD(KDK[[#This Row],[Total Brick]],100)>40,KDK[[#This Row],[Total Brick]] - MOD(KDK[[#This Row],[Total Brick]],100)+50,KDK[[#This Row],[Total Brick]] - MOD(KDK[[#This Row],[Total Brick]],100))) -> 0 | J3: =_xlfn.IFNA(1.5,0) -> 1.5 | K3: =KDK[[#This Row],[Round Total Brick]]*KDK[[#This Row],[Amount of pre brick]] -> 0
A4: =ROW()-1 -> 3 | B4: 45566 | C4: =TEXT(KDK[[#This Row],[Date]],"dddd") -> Tuesday | D4: =WEEKNUM(KDK[[#This Row],[Date]],2) -> 40 | E4: Ramseesh | F4: 25 | G4: 45 | H4: =KDK[[#This Row],[Brick]]*KDK[[#This Row],[Line]] -> 1125 | I4: =IF(MOD(KDK[[#This Row],[Total Brick]],100)>90,KDK[[#This Row],[Total Brick]] - MOD(KDK[[#This Row],[Total Brick]],100) + 100,IF(MOD(KDK[[#This Row],[Total Brick]],100)>40,KDK[[#This Row],[Total Brick]] - MOD(KDK[[#This Row],[Total Brick]],100)+50,KDK[[#This Row],[Total Brick]] - MOD(KDK[[#This Row],[Total Brick]],100))) -> 1100 | J4: =_xlfn.IFNA(1.5,0) -> 1.5 | K4: =KDK[[#This Row],[Round Total Brick]]*KDK[[#This Row],[Amount of pre brick]] -> 1650
A5: =ROW()-1 -> 4 | B5: 45566 | C5: =TEXT(KDK[[#This Row],[Date]],"dddd") -> Tuesday | D5: =WEEKNUM(KDK[[#This Row],[Date]],2) -> 40 | E5: Settu | F5: =_xlfn.IFNA(0,0) -> 0 | G5: =_xlfn.IFNA(0,0) -> 0 | H5: =KDK[[#This Row],[Brick]]*KDK[[#This Row],[Line]] -> 0 | I5: =IF(MOD(KDK[[#This Row],[Total Brick]],100)>90,KDK[[#This Row],[Total Brick]] - MOD(KDK[[#This Row],[Total Brick]],100) + 100,IF(MOD(KDK[[#This Row],[Total Brick]],100)>40,KDK[[#This Row],[Total Brick]] - MOD(KDK[[#This Row],[Total Brick]],100)+50,KDK[[#This Row],[Total Brick]] - MOD(KDK[[#This Row],[Total Brick]],100))) -> 0 | J5: =_xlfn.IFNA(1.5,0) -> 1.5 | K5: =KDK[[#This Row],[Round Total Brick]]*KDK[[#This Row],[Amount of pre brick]] -> 0
A6: =ROW()-1 -> 5 | B6: 45566 | C6: =TEXT(KDK[[#This Row],[Date]],"dddd") -> Tuesday | D6: =WEEKNUM(KDK[[#This Row],[Date]],2) -> 40 | E6: Dhurai | F6: =_xlfn.IFNA(0,0) -> 0 | G6: =_xlfn.IFNA(0,0) -> 0 | H6: =KDK[[#This Row],[Brick]]*KDK[[#This Row],[Line]] -> 0 | I6: =IF(MOD(KDK[[#This Row],[Total Brick]],100)>90,KDK[[#This Row],[Total Brick]] - MOD(KDK[[#This Row],[Total Brick]],100) + 100,IF(MOD(KDK[[#This Row],[Total Brick]],100)>40,KDK[[#This Row],[Total Brick]] - MOD(KDK[[#This Row],[Total Brick]],100)+50,KDK[[#This Row],[Total Brick]] - MOD(KDK[[#This Row],[Total Brick]],100))) -> 0 | J6: =_xlfn.IFNA(1.5,0) -> 1.5 | K6: =KDK[[#This Row],[Round Total Brick]]*KDK[[#This Row],[Amount of pre brick]] -> 0
A7: =ROW()-1 -> 6 | B7: 45566 | C7: =TEXT(KDK[[#This Row],[Date]],"dddd") -> Tuesday | D7: =WEEKNUM(KDK[[#This Row],[Date]],2) -> 40 | E7: Ramesh | F7: =_xlfn.IFNA(0,0) -> 0 | G7: =_xlfn.IFNA(0,0) -> 0 | H7: =KDK[[#This Row],[Brick]]*KDK[[#This Row],[Line]] -> 0 | I7: =IF(MOD(KDK[[#This Row],[Total Brick]],100)>90,KDK[[#This Row],[Total Brick]] - MOD(KDK[[#This Row],[Total Brick]],100) + 100,IF(MOD(KDK[[#This Row],[Total Brick]],100)>40,KDK[[#This Row],[Total Brick]] - MOD(KDK[[#This Row],[Total Brick]],100)+50,KDK[[#This Row],[Total Brick]] - MOD(KDK[[#This Row],[Total Brick]],100))) -> 0 | J7: =_xlfn.IFNA(1.5,0) -> 1.5 | K7: =KDK[[#This Row],[Round Total Brick]]*KDK[[#This Row],[Amount of pre brick]] -> 0
A8: =ROW()-1 -> 7 | B8: 45566 | C8: =TEXT(KDK[[#This Row],[Date]],"dddd") -> Tuesday | D8: =WEEKNUM(KDK[[#This Row],[Date]],2) -> 40 | E8: Ram Charan | F8: =_xlfn.IFNA(0,0) -> 0 | G8: =_xlfn.IFNA(0,0) -> 0 | H8: =KDK[[#This Row],[Brick]]*KDK[[#This Row],[Line]] -> 0 | I8: =IF(MOD(KDK[[#This Row],[Total Brick]],100)>90,KDK[[#This Row],[Total Brick]] - MOD(KDK[[#This Row],[Total Brick]],100) + 100,IF(MOD(KDK[[#This Row],[Total Brick]],100)>40,KDK[[#This Row],[Total Brick]] - MOD(KDK[[#This Row],[Total Brick]],100)+50,KDK[[#This Row],[Total Brick]] - MOD(KDK[[#This Row],[Total Brick]],100))) -> 0 | J8: =_xlfn.IFNA(1.5,0) -> 1.5 | K8: =KDK[[#This Row],[Round Total Brick]]*KDK[[#This Row],[Amount of pre brick]] -> 0
A9: =ROW()-1 -> 8 | B9: 45567 | C9: =TEXT(KDK[[#This Row],[Date]],"dddd") -> Wednesday | D9: =WEEKNUM(KDK[[#This Row],[Date]],2) -> 40 | E9: Aakash | F9: 27 | G9: 42 | H9: =KDK[[#This Row],[Brick]]*KDK[[#This Row],[Line]] -> 1134 | I9: =IF(MOD(KDK[[#This Row],[Total Brick]],100)>90,KDK[[#This Row],[Total Brick]] - MOD(KDK[[#This Row],[Total Brick]],100) + 100,IF(MOD(KDK[[#This Row],[Total Brick]],100)>40,KDK[[#This Row],[Total Brick]] - MOD(KDK[[#This Row],[Total Brick]],100)+50,KDK[[#This Row],[Total Brick]] - MOD(KDK[[#This Row],[Total Brick]],100))) -> 1100 | J9: =_xlfn.IFNA(1.5,0) -> 1.5 | K9: =KDK[[#This Row],[Round Total Brick]]*KDK[[#This Row],[Amount of pre brick]] -> 1650
A10: =ROW()-1 -> 9 | B10: 45567 | C10: =TEXT(KDK[[#This Row],[Date]],"dddd") -> Wednesday | D10: =WEEKNUM(KDK[[#This Row],[Date]],2) -> 40 | E10: Mahesh | F10: =_xlfn.IFNA(0,0) -> 0 | G10: =_xlfn.IFNA(0,0) -> 0 | H10: =KDK[[#This Row],[Brick]]*KDK[[#This Row],[Line]] -> 0 | I10: =IF(MOD(KDK[[#This Row],[Total Brick]],100)>90,KDK[[#This Row],[Total Brick]] - MOD(KDK[[#This Row],[Total Brick]],100) + 100,IF(MOD(KDK[[#This Row],[Total Brick]],100)>40,KDK[[#This Row],[Total Brick]] - MOD(KDK[[#This Row],[Total Brick]],100)+50,KDK[[#This Row],[Total Brick]] - MOD(KDK[[#This Row],[Total Brick]],100))) -> 0 | J10: =_xlfn.IFNA(1.5,0) -> 1.5 | K10: =KDK[[#This Row],[Round Total Brick]]*KDK[[#This Row],[Amount of pre brick]] -> 0
A11: =ROW()-1 -> 10 | B11: 45567 | C11: =TEXT(KDK[[#This Row],[Date]],"dddd") -> Wednesday | D11: =WEEKNUM(KDK[[#This Row],[Date]],2) -> 40 | E11: Ramseesh | F11: 26 | G11: 39 | H11: =KDK[[#This Row],[Brick]]*KDK[[#This Row],[Line]] -> 1014 | I11: =IF(MOD(KDK[[#This Row],[Total Brick]],100)>90,KDK[[#This Row],[Total Brick]] - MOD(KDK[[#This Row],[Total Brick]],100) + 100,IF(MOD(KDK[[#This Row],[Total Brick]],100)>40,KDK[[#This Row],[Total Brick]] - MOD(KDK[[#This Row],[Total Brick]],100)+50,KDK[[#This Row],[Total Brick]] - MOD(KDK[[#This Row],[Total Brick]],100))) -> 1000 | J11: =_xlfn.IFNA(1.5,0) -> 1.5 | K11: =KDK[[#This Row],[Round Total Brick]]*KDK[[#This Row],[Amount of pre brick]] -> 1500
A12: =ROW()-1 -> 11 | B12: 45567 | C12: =TEXT(KDK[[#This Row],[Date]],"dddd") -> Wednesday | D12: =WEEKNUM(KDK[[#This Row],[Date]],2) -> 40 | E12: Settu | F12: 25 | G12: 27 | H12: =KDK[[#This Row],[Brick]]*KDK[[#This Row],[Line]] -> 675 | I12: =IF(MOD(KDK[[#This Row],[Total Brick]],100)>90,KDK[[#This Row],[Total Brick]] - MOD(KDK[[#This Row],[Total Brick]],100) + 100,IF(MOD(KDK[[#This Row],[Total Brick]],100)>40,KDK[[#This Row],[Total Brick]] - MOD(KDK[[#This Row],[Total Brick]],100)+50,KDK[[#This Row],[Total Brick]] - MOD(KDK[[#This Row],[Total Brick]],100))) -> 650 | J12: =_xlfn.IFNA(1.5,0) -> 1.5 | K12: =KDK[[#This Row],[Round Total Brick]]*KDK[[#This Row],[Amount of pre brick]] -> 975
A13: =ROW()-1 -> 12 | B13: 45567 | C13: =TEXT(KDK[[#This Row],[Date]],"dddd") -> Wednesday | D13: =WEEKNUM(KDK[[#This Row],[Date]],2) -> 40 | E13: Settu | F13: 28 | G13: 25 | H13: =KDK[[#This Row],[Brick]]*KDK[[#This Row],[Line]] -> 700 | I13: =IF(MOD(KDK[[#This Row],[Total Brick]],100)>90,KDK[[#This Row],[Total Brick]] - MOD(KDK[[#This Row],[Total Brick]],100) + 100,IF(MOD(KDK[[#This Row],[Total Brick]],100)>40,KDK[[#This Row],[Total Brick]] - MOD(KDK[[#This Row],[Total Brick]],100)+50,KDK[[#This Row],[Total Brick]] - MOD(KDK[[#This Row],[Total Brick]],100))) -> 700 | J13: =_xlfn.IFNA(1.5,0) -> 1.5 | K13: =KDK[[#This Row],[Round Total Brick]]*KDK[[#This Row],[Amount of pre brick]] -> 1050
A14: =ROW()-1 -> 13 | B14: 45567 | C14: =TEXT(KDK[[#This Row],[Date]],"dddd") -> Wednesday | D14: =WEEKNUM(KDK[[#This Row],[Date]],2) -> 40 | E14: Dhurai | F14: =_xlfn.IFNA(0,0) -> 0 | G14: =_xlfn.IFNA(0,0) -> 0 | H14: =KDK[[#This Row],[Brick]]*KDK[[#This Row],[Line]] -> 0 | I14: =IF(MOD(KDK[[#This Row],[Total Brick]],100)>90,KDK[[#This Row],[Total Brick]] - MOD(KDK[[#This Row],[Total Brick]],100) + 100,IF(MOD(KDK[[#This Row],[Total Brick]],100)>40,KDK[[#This Row],[Total Brick]] - MOD(KDK[[#This Row],[Total Brick]],100)+50,KDK[[#This Row],[Total Brick]] - MOD(KDK[[#This Row],[Total Brick]],100))) -> 0 | J14: =_xlfn.IFNA(1.5,0) -> 1.5 | K14: =KDK[[#This Row],[Round Total Brick]]*KDK[[#This Row],[Amount of pre brick]] -> 0
A15: =ROW()-1 -> 14 | B15: 45567 | C15: =TEXT(KDK[[#This Row],[Date]],"dddd") -> Wednesday | D15: =WEEKNUM(KDK[[#This Row],[Date]],2) -> 40 | E15: Ramesh | F15: =_xlfn.IFNA(0,0) -> 0 | G15: =_xlfn.IFNA(0,0) -> 0 | H15: =KDK[[#This Row],[Brick]]*KDK[[#This Row],[Line]] -> 0 | I15: =IF(MOD(KDK[[#This Row],[Total Brick]],100)>90,KDK[[#This Row],[Total Brick]] - MOD(KDK[[#This Row],[Total Brick]],100) + 100,IF(MOD(KDK[[#This Row],[Total Brick]],100)>40,KDK[[#This Row],[Total Brick]] - MOD(KDK[[#This Row],[Total Brick]],100)+50,KDK[[#This Row],[Total Brick]] - MOD(KDK[[#This Row],[Total Brick]],100))) -> 0 | J15: =_xlfn.IFNA(1.5,0) -> 1.5 | K15: =KDK[[#This Row],[Round Total Brick]]*KDK[[#This Row],[Amount of pre brick]] -> 0
A16: =ROW()-1 -> 15 | B16: 45567 | C16: =TEXT(KDK[[#This Row],[Date]],"dddd") -> Wednesday | D16: =WEEKNUM(KDK[[#This Row],[Date]],2) -> 40 | E16: Ram Charan | F16: =_xlfn.IFNA(0,0) -> 0 | G16: =_xlfn.IFNA(0,0) -> 0 | H16: =KDK[[#This Row],[Brick]]*KDK[[#This Row],[Line]] -> 0 | I16: =IF(MOD(KDK[[#This Row],[Total Brick]],100)>90,KDK[[#This Row],[Total Brick]] - MOD(KDK[[#This Row],[Total Brick]],100) + 100,IF(MOD(KDK[[#This Row],[Total Brick]],100)>40,KDK[[#This Row],[Total Brick]] - MOD(KDK[[#This Row],[Total Brick]],100)+50,KDK[[#This Row],[Total Brick]] - MOD(KDK[[#This Row],[Total Brick]],100))) -> 0 | J16: =_xlfn.IFNA(1.5,0) -> 1.5 | K16: =KDK[[#This Row],[Round Total Brick]]*KDK[[#This Row],[Amount of pre brick]] -> 0
A17: =ROW()-1 -> 16 | B17: 45568 | C17: =TEXT(KDK[[#This Row],[Date]],"dddd") -> Thursday | D17: =WEEKNUM(KDK[[#This Row],[Date]],2) -> 40 | E17: Aakash | F17: =_xlfn.IFNA(0,0) -> 0 | G17: =_xlfn.IFNA(0,0) -> 0 | H17: =KDK[[#This Row],[Brick]]*KDK[[#This Row],[Line]] -> 0 | I17: =IF(MOD(KDK[[#This Row],[Total Brick]],100)>90,KDK[[#This Row],[Total Brick]] - MOD(KDK[[#This Row],[Total Brick]],100) + 100,IF(MOD(KDK[[#This Row],[Total Brick]],100)>40,KDK[[#This Row],[Total Brick]] - MOD(KDK[[#This Row],[Total Brick]],100)+50,KDK[[#This Row],[Total Brick]] - MOD(KDK[[#This Row],[Total Brick]],100))) -> 0 | J17: =_xlfn.IFNA(1.5,0) -> 1.5 | K17: =KDK[[#This Row],[Round Total Brick]]*KDK[[#This Row],[Amount of pre brick]] -> 0
A18: =ROW()-1 -> 17 | B18: 45568 | C18: =TEXT(KDK[[#This Row],[Date]],"dddd") -> Thursday | D18: =WEEKNUM(KDK[[#This Row],[Date]],2) -> 40 | E18: Mahesh | F18: =_xlfn.IFNA(0,0) -> 0 | G18: =_xlfn.IFNA(0,0) -> 0 | H18: =KDK[[#This Row],[Brick]]*KDK[[#This Row],[Line]] -> 0 | I18: =IF(MOD(KDK[[#This Row],[Total Brick]],100)>90,KDK[[#This Row],[Total Brick]] - MOD(KDK[[#This Row],[Total Brick]],100) + 100,IF(MOD(KDK[[#This Row],[Total Brick]],100)>40,KDK[[#This Row],[Total Brick]] - MOD(KDK[[#This Row],[Total Brick]],100)+50,KDK[[#This Row],[Total Brick]] - MOD(KDK[[#This Row],[Total Brick]],100))) -> 0 | J18: =_xlfn.IFNA(1.5,0) -> 1.5 | K18: =KDK[[#This Row],[Round Total Brick]]*KDK[[#This Row],[Amount of pre brick]] -> 0
A19: =ROW()-1 -> 18 | B19: 45568 | C19: =TEXT(KDK[[#This Row],[Date]],"dddd") -> Thursday | D19: =WEEKNUM(KDK[[#This Row],[Date]],2) -> 40 | E19: Ramseesh | F19: =_xlfn.IFNA(0,0) -> 0 | G19: =_xlfn.IFNA(0,0) -> 0 | H19: =KDK[[#This Row],[Brick]]*KDK[[#This Row],[Line]] -> 0 | I19: =IF(MOD(KDK[[#This Row],[Total Brick]],100)>90,KDK[[#This Row],[Total Brick]] - MOD(KDK[[#This Row],[Total Brick]],100) + 100,IF(MOD(KDK[[#This Row],[Total Brick]],100)>40,KDK[[#This Row],[Total Brick]] - MOD(KDK[[#This Row],[Total Brick]],100)+50,KDK[[#This Row],[Total Brick]] - MOD(KDK[[#This Row],[Total Brick]],100))) -> 0 | J19: =_xlfn.IFNA(1.5,0) -> 1.5 | K19: =KDK[[#This Row],[Round Total Brick]]*KDK[[#This Row],[Amount of pre brick]] -> 0
A20: =ROW()-1 -> 19 | B20: 45568 | C20: =TEXT(KDK[[#This Row],[Date]],"dddd") -> Thursday | D20: =WEEKNUM(KDK[[#This Row],[Date]],2) -> 40 | E20: Settu | F20: 29 | G20: 53 | H20: =KDK[[#This Row],[Brick]]*KDK[[#This Row],[Line]] -> 1537 | I20: =IF(MOD(KDK[[#This Row],[Total Brick]],100)>90,KDK[[#This Row],[Total Brick]] - MOD(KDK[[#This Row],[Total Brick]],100) + 100,IF(MOD(KDK[[#This Row],[Total Brick]],100)>40,KDK[[#This Row],[Total Brick]] - MOD(KDK[[#This Row],[Total Brick]],100)+50,KDK[[#This Row],[Total Brick]] - MOD(KDK[[#This Row],[Total Brick]],100))) -> 1500 | J20: =_xlfn.IFNA(1.5,0) -> 1.5 | K20: =KDK[[#This Row],[Round Total Brick]]*KDK[[#This Row],[Amount of pre brick]] -> 2250
A21: =ROW()-1 -> 20 | B21: 45568 | C21: =TEXT(KDK[[#This Row],[Date]],"dddd") -> Thursday | D21: =WEEKNUM(KDK[[#This Row],[Date]],2) -> 40 | E21: Dhurai | F21: =_xlfn.IFNA(0,0) -> 0 | G21: =_xlfn.IFNA(0,0) -> 0 | H21: =KDK[[#This Row],[Brick]]*KDK[[#This Row],[Line]] -> 0 | I21: =IF(MOD(KDK[[#This Row],[Total Brick]],100)>90,KDK[[#This Row],[Total Brick]] - MOD(KDK[[#This Row],[Total Brick]],100) + 100,IF(MOD(KDK[[#This Row],[Total Brick]],100)>40,KDK[[#This Row],[Total Brick]] - MOD(KDK[[#This Row],[Total Brick]],100)+50,KDK[[#This Row],[Total Brick]] - MOD(KDK[[#This Row],[Total Brick]],100))) -> 0 | J21: =_xlfn.IFNA(1.5,0) -> 1.5 | K21: =KDK[[#This Row],[Round Total Brick]]*KDK[[#This Row],[Amount of pre brick]] -> 0
A22: =ROW()-1 -> 21 | B22: 45568 | C22: =TEXT(KDK[[#This Row],[Date]],"dddd") -> Thursday | D22: =WEEKNUM(KDK[[#This Row],[Date]],2) -> 40 | E22: Ramesh | F22: =_xlfn.IFNA(0,0) -> 0 | G22: =_xlfn.IFNA(0,0) -> 0 | H22: =KDK[[#This Row],[Brick]]*KDK[[#This Row],[Line]] -> 0 | I22: =IF(MOD(KDK[[#This Row],[Total Brick]],100)>90,KDK[[#This Row],[Total Brick]] - MOD(KDK[[#This Row],[Total Brick]],100) + 100,IF(MOD(KDK[[#This Row],[Total Brick]],100)>40,KDK[[#This Row],[Total Brick]] - MOD(KDK[[#This Row],[Total Brick]],100)+50,KDK[[#This Row],[Total Brick]] - MOD(KDK[[#This Row],[Total Brick]],100))) -> 0 | J22: =_xlfn.IFNA(1.5,0) -> 1.5 | K22: =KDK[[#This Row],[Round Total Brick]]*KDK[[#This Row],[Amount of pre brick]] -> 0
A23: =ROW()-1 -> 22 | B23: 45568 | C23: =TEXT(KDK[[#This Row],[Date]],"dddd") -> Thursday | D23: =WEEKNUM(KDK[[#This Row],[Date]],2) -> 40 | E23: Ram Charan | F23: =_xlfn.IFNA(0,0) -> 0 | G23: =_xlfn.IFNA(0,0) -> 0 | H23: =KDK[[#This Row],[Brick]]*KDK[[#This Row],[Line]] -> 0 | I23: =IF(MOD(KDK[[#This Row],[Total Brick]],100)>90,KDK[[#This Row],[Total Brick]] - MOD(KDK[[#This Row],[Total Brick]],100) + 100,IF(MOD(KDK[[#This Row],[Total Brick]],100)>40,KDK[[#This Row],[Total Brick]] - MOD(KDK[[#This Row],[Total Brick]],100)+50,KDK[[#This Row],[Total Brick]] - MOD(KDK[[#This Row],[Total Brick]],100))) -> 0 | J23: =_xlfn.IFNA(1.5,0) -> 1.5 | K23: =KDK[[#This Row],[Round Total Brick]]*KDK[[#This Row],[Amount of pre brick]] -> 0
A24: =ROW()-1 -> 23 | B24: 45569 | C24: =TEXT(KDK[[#This Row],[Date]],"dddd") -> Friday | D24: =WEEKNUM(KDK[[#This Row],[Date]],2) -> 40 | E24: Aakash | F24: 26 | G24: 43 | H24: =KDK[[#This Row],[Brick]]*KDK[[#This Row],[Line]] -> 1118 | I24: =IF(MOD(KDK[[#This Row],[Total Brick]],100)>90,KDK[[#This Row],[Total Brick]] - MOD(KDK[[#This Row],[Total Brick]],100) + 100,IF(MOD(KDK[[#This Row],[Total Brick]],100)>40,KDK[[#This Row],[Total Brick]] - MOD(KDK[[#This Row],[Total Brick]],100)+50,KDK[[#This Row],[Total Brick]] - MOD(KDK[[#This Row],[Total Brick]],100))) -> 1100 | J24: =_xlfn.IFNA(1.5,0) -> 1.5 | K24: =KDK[[#This Row],[Round Total Brick]]*KDK[[#This Row],[Amount of pre brick]] -> 1650
A25: =ROW()-1 -> 24 | B25: 45569 | C25: =TEXT(KDK[[#This Row],[Date]],"dddd") -> Friday | D25: =WEEKNUM(KDK[[#This Row],[Date]],2) -> 40 | E25: Mahesh | F25: =_xlfn.IFNA(0,0) -> 0 | G25: =_xlfn.IFNA(0,0) -> 0 | H25: =KDK[[#This Row],[Brick]]*KDK[[#This Row],[Line]] -> 0 | I25: =IF(MOD(KDK[[#This Row],[Total Brick]],100)>90,KDK[[#This Row],[Total Brick]] - MOD(KDK[[#This Row],[Total Brick]],100) + 100,IF(MOD(KDK[[#This Row],[Total Brick]],100)>40,KDK[[#This Row],[Total Brick]] - MOD(KDK[[#This Row],[Total Brick]],100)+50,KDK[[#This Row],[Total Brick]] - MOD(KDK[[#This Row],[Total Brick]],100))) -> 0 | J25: =_xlfn.IFNA(1.5,0) -> 1.5 | K25: =KDK[[#This Row],[Round Total Brick]]*KDK[[#This Row],[Amount of pre brick]] -> 0
A26: =ROW()-1 -> 25 | B26: 45569 | C26: =TEXT(KDK[[#This Row],[Date]],"dddd") -> Friday | D26: =WEEKNUM(KDK[[#This Row],[Date]],2) -> 40 | E26: Ramseesh | F26: =_xlfn.IFNA(0,0) -> 0 | G26: =_xlfn.IFNA(0,0) -> 0 | H26: =KDK[[#This Row],[Brick]]*KDK[[#This Row],[Line]] -> 0 | I26: =IF(MOD(KDK[[#This Row],[Total Brick]],100)>90,KDK[[#This Row],[Total Brick]] - MOD(KDK[[#This Row],[Total Brick]],100) + 100,IF(MOD(KDK[[#This Row],[Total Brick]],100)>40,KDK[[#This Row],[Total Brick]] - MOD(KDK[[#This Row],[Total Brick]],100)+50,KDK[[#This Row],[Total Brick]] - MOD(KDK[[#This Row],[Total Brick]],100))) -> 0 | J26: =_xlfn.IFNA(1.5,0) -> 1.5 | K26: =KDK[[#This Row],[Round Total Brick]]*KDK[[#This Row],[Amount of pre brick]] -> 0
A27: =ROW()-1 -> 26 | B27: 45569 | C27: =TEXT(KDK[[#This Row],[Date]],"dddd") -> Friday | D27: =WEEKNUM(KDK[[#This Row],[Date]],2) -> 40 | E27: Settu | F27: =_xlfn.IFNA(0,0) -> 0 | G27: =_xlfn.IFNA(0,0) -> 0 | H27: =KDK[[#This Row],[Brick]]*KDK[[#This Row],[Line]] -> 0 | I27: =IF(MOD(KDK[[#This Row],[Total Brick]],100)>90,KDK[[#This Row],[Total Brick]] - MOD(KDK[[#This Row],[Total Brick]],100) + 100,IF(MOD(KDK[[#This Row],[Total Brick]],100)>40,KDK[[#This Row],[Total Brick]] - MOD(KDK[[#This Row],[Total Brick]],100)+50,KDK[[#This Row],[Total Brick]] - MOD(KDK[[#This Row],[Total Brick]],100))) -> 0 | J27: =_xlfn.IFNA(1.5,0) -> 1.5 | K27: =KDK[[#This Row],[Round Total Brick]]*KDK[[#This Row],[Amount of pre brick]] -> 0
A28: =ROW()-1 -> 27 | B28: 45569 | C28: =TEXT(KDK[[#This Row],[Date]],"dddd") -> Friday | D28: =WEEKNUM(KDK[[#This Row],[Date]],2) -> 40 | E28: Dhurai | F28: 28 | G28: 45 | H28: =KDK[[#This Row],[Brick]]*KDK[[#This Row],[Line]] -> 1260 | I28: =IF(MOD(KDK[[#This Row],[Total Brick]],100)>90,KDK[[#This Row],[Total Brick]] - MOD(KDK[[#This Row],[Total Brick]],100) + 100,IF(MOD(KDK[[#This Row],[Total Brick]],100)>40,KDK[[#This Row],[Total Brick]] - MOD(KDK[[#This Row],[Total Brick]],100)+50,KDK[[#This Row],[Total Brick]] - MOD(KDK[[#This Row],[Total Brick]],100))) -> 1250 | J28: =_xlfn.IFNA(1.5,0) -> 1.5 | K28: =KDK[[#This Row],[Round Total Brick]]*KDK[[#This Row],[Amount of pre brick]] -> 1875
A29: =ROW()-1 -> 28 | B29: 45569 | C29: =TEXT(KDK[[#This Row],[Date]],"dddd") -> Friday | D29: =WEEKNUM(KDK[[#This Row],[Date]],2) -> 40 | E29: Ramesh | F29: =_xlfn.IFNA(0,0) -> 0 | G29: =_xlfn.IFNA(0,0) -> 0 | H29: =KDK[[#This Row],[Brick]]*KDK[[#This Row],[Line]] -> 0 | I29: =IF(MOD(KDK[[#This Row],[Total Brick]],100)>90,KDK[[#This Row],[Total Brick]] - MOD(KDK[[#This Row],[Total Brick]],100) + 100,IF(MOD(KDK[[#This Row],[Total Brick]],100)>40,KDK[[#This Row],[Total Brick]] - MOD(KDK[[#This Row],[Total Brick]],100)+50,KDK[[#This Row],[Total Brick]] - MOD(KDK[[#This Row],[Total Brick]],100))) -> 0 | J29: =_xlfn.IFNA(1.5,0) -> 1.5 | K29: =KDK[[#This Row],[Round Total Brick]]*KDK[[#This Row],[Amount of pre brick]] -> 0
A30: =ROW()-1 -> 29 | B30: 45569 | C30: =TEXT(KDK[[#This Row],[Date]],"dddd") -> Friday | D30: =WEEKNUM(KDK[[#This Row],[Date]],2) -> 40 | E30: Ram Charan | F30: =_xlfn.IFNA(0,0) -> 0 | G30: =_xlfn.IFNA(0,0) -> 0 | H30: =KDK[[#This Row],[Brick]]*KDK[[#This Row],[Line]] -> 0 | I30: =IF(MOD(KDK[[#This Row],[Total Brick]],100)>90,KDK[[#This Row],[Total Brick]] - MOD(KDK[[#This Row],[Total Brick]],100) + 100,IF(MOD(KDK[[#This Row],[Total Brick]],100)>40,KDK[[#This Row],[Total Brick]] - MOD(KDK[[#This Row],[Total Brick]],100)+50,KDK[[#This Row],[Total Brick]] - MOD(KDK[[#This Row],[Total Brick]],100))) -> 0 | J30: =_xlfn.IFNA(1.5,0) -> 1.5 | K30: =KDK[[#This Row],[Round Total Brick]]*KDK[[#This Row],[Amount of pre brick]] -> 0
A31: =ROW()-1 -> 30 | B31: 45570 | C31: =TEXT(KDK[[#This Row],[Date]],"dddd") -> Saturday | D31: =WEEKNUM(KDK[[#This Row],[Date]],2) -> 40 | E31: Aakash | F31: =_xlfn.IFNA(0,0) -> 0 | G31: =_xlfn.IFNA(0,0) -> 0 | H31: =KDK[[#This Row],[Brick]]*KDK[[#This Row],[Line]] -> 0 | I31: =IF(MOD(KDK[[#This Row],[Total Brick]],100)>90,KDK[[#This Row],[Total Brick]] - MOD(KDK[[#This Row],[Total Brick]],100) + 100,IF(MOD(KDK[[#This Row],[Total Brick]],100)>40,KDK[[#This Row],[Total Brick]] - MOD(KDK[[#This Row],[Total Brick]],100)+50,KDK[[#This Row],[Total Brick]] - MOD(KDK[[#This Row],[Total Brick]],100))) -> 0 | J31: =_xlfn.IFNA(1.5,0) -> 1.5 | K31: =KDK[[#This Row],[Round Total Brick]]*KDK[[#This Row],[Amount of pre brick]] -> 0
A32: =ROW()-1 -> 31 | B32: 45570 | C32: =TEXT(KDK[[#This Row],[Date]],"dddd") -> Saturday | D32: =WEEKNUM(KDK[[#This Row],[Date]],2) -> 40 | E32: Mahesh | F32: =_xlfn.IFNA(0,0) -> 0 | G32: =_xlfn.IFNA(0,0) -> 0 | H32: =KDK[[#This Row],[Brick]]*KDK[[#This Row],[Line]] -> 0 | I32: =IF(MOD(KDK[[#This Row],[Total Brick]],100)>90,KDK[[#This Row],[Total Brick]] - MOD(KDK[[#This Row],[Total Brick]],100) + 100,IF(MOD(KDK[[#This Row],[Total Brick]],100)>40,KDK[[#This Row],[Total Brick]] - MOD(KDK[[#This Row],[Total Brick]],100)+50,KDK[[#This Row],[Total Brick]] - MOD(KDK[[#This Row],[Total Brick]],100))) -> 0 | J32: =_xlfn.IFNA(1.5,0) -> 1.5 | K32: =KDK[[#This Row],[Round Total Brick]]*KDK[[#This Row],[Amount of pre brick]] -> 0
A33: =ROW()-1 -> 32 | B33: 45570 | C33: =TEXT(KDK[[#This Row],[Date]],"dddd") -> Saturday | D33: =WEEKNUM(KDK[[#This Row],[Date]],2) -> 40 | E33: Ramseesh | F33: =_xlfn.IFNA(0,0) -> 0 | G33: =_xlfn.IFNA(0,0) -> 0 | H33: =KDK[[#This Row],[Brick]]*KDK[[#This Row],[Line]] -> 0 | I33: =IF(MOD(KDK[[#This Row],[Total Brick]],100)>90,KDK[[#This Row],[Total Brick]] - MOD(KDK[[#This Row],[Total Brick]],100) + 100,IF(MOD(KDK[[#This Row],[Total Brick]],100)>40,KDK[[#This Row],[Total Brick]] - MOD(KDK[[#This Row],[Total Brick]],100)+50,KDK[[#This Row],[Total Brick]] - MOD(KDK[[#This Row],[Total Brick]],100))) -> 0 | J33: =_xlfn.IFNA(1.5,0) -> 1.5 | K33: =KDK[[#This Row],[Round Total Brick]]*KDK[[#This Row],[Amount of pre brick]] -> 0
A34: =ROW()-1 -> 33 | B34: 45570 | C34: =TEXT(KDK[[#This Row],[Date]],"dddd") -> Saturday | D34: =WEEKNUM(KDK[[#This Row],[Date]],2) -> 40 | E34: Settu | F34: =_xlfn.IFNA(0,0) -> 0 | G34: =_xlfn.IFNA(0,0) -> 0 | H34: =KDK[[#This Row],[Brick]]*KDK[[#This Row],[Line]] -> 0 | I34: =IF(MOD(KDK[[#This Row],[Total Brick]],100)>90,KDK[[#This Row],[Total Brick]] - MOD(KDK[[#This Row],[Total Brick]],100) + 100,IF(MOD(KDK[[#This Row],[Total Brick]],100)>40,KDK[[#This Row],[Total Brick]] - MOD(KDK[[#This Row],[Total Brick]],100)+50,KDK[[#This Row],[Total Brick]] - MOD(KDK[[#This Row],[Total Brick]],100))) -> 0 | J34: =_xlfn.IFNA(1.5,0) -> 1.5 | K34: =KDK[[#This Row],[Round Total Brick]]*KDK[[#This Row],[Amount of pre brick]] -> 0
A35: =ROW()-1 -> 34 | B35: 45570 | C35: =TEXT(KDK[[#This Row],[Date]],"dddd") -> Saturday | D35: =WEEKNUM(KDK[[#This Row],[Date]],2) -> 40 | E35: Dhurai | F35: =_xlfn.IFNA(0,0) -> 0 | G35: =_xlfn.IFNA(0,0) -> 0 | H35: =KDK[[#This Row],[Brick]]*KDK[[#This Row],[Line]] -> 0 | I35: =IF(MOD(KDK[[#This Row],[Total Brick]],100)>90,KDK[[#This Row],[Total Brick]] - MOD(KDK[[#This Row],[Total Brick]],100) + 100,IF(MOD(KDK[[#This Row],[Total Brick]],100)>40,KDK[[#This Row],[Total Brick]] - MOD(KDK[[#This Row],[Total Brick]],100)+50,KDK[[#This Row],[Total Brick]] - MOD(KDK[[#This Row],[Total Brick]],100))) -> 0 | J35: =_xlfn.IFNA(1.5,0) -> 1.5 | K35: =KDK[[#This Row],[Round Total Brick]]*KDK[[#This Row],[Amount of pre brick]] -> 0
A36: =ROW()-1 -> 35 | B36: 45570 | C36: =TEXT(KDK[[#This Row],[Date]],"dddd") -> Saturday | D36: =WEEKNUM(KDK[[#This Row],[Date]],2) -> 40 | E36: Ramesh | F36: =_xlfn.IFNA(0,0) -> 0 | G36: =_xlfn.IFNA(0,0) -> 0 | H36: =KDK[[#This Row],[Brick]]*KDK[[#This Row],[Line]] -> 0 | I36: =IF(MOD(KDK[[#This Row],[Total Brick]],100)>90,KDK[[#This Row],[Total Brick]] - MOD(KDK[[#This Row],[Total Brick]],100) + 100,IF(MOD(KDK[[#This Row],[Total Brick]],100)>40,KDK[[#This Row],[Total Brick]] - MOD(KDK[[#This Row],[Total Brick]],100)+50,KDK[[#This Row],[Total Brick]] - MOD(KDK[[#This Row],[Total Brick]],100))) -> 0 | J36: =_xlfn.IFNA(1.5,0) -> 1.5 | K36: =KDK[[#This Row],[Round Total Brick]]*KDK[[#This Row],[Amount of pre brick]] -> 0
A37: =ROW()-1 -> 36 | B37: 45570 | C37: =TEXT(KDK[[#This Row],[Date]],"dddd") -> Saturday | D37: =WEEKNUM(KDK[[#This Row],[Date]],2) -> 40 | E37: Ram Charan | F37: =_xlfn.IFNA(0,0) -> 0 | G37: =_xlfn.IFNA(0,0) -> 0 | H37: =KDK[[#This Row],[Brick]]*KDK[[#This Row],[Line]] -> 0 | I37: =IF(MOD(KDK[[#This Row],[Total Brick]],100)>90,KDK[[#This Row],[Total Brick]] - MOD(KDK[[#This Row],[Total Brick]],100) + 100,IF(MOD(KDK[[#This Row],[Total Brick]],100)>40,KDK[[#This Row],[Total Brick]] - MOD(KDK[[#This Row],[Total Brick]],100)+50,KDK[[#This Row],[Total Brick]] - MOD(KDK[[#This Row],[Total Brick]],100))) -> 0 | J37: =_xlfn.IFNA(1.5,0) -> 1.5 | K37: =KDK[[#This Row],[Round Total Brick]]*KDK[[#This Row],[Amount of pre brick]] -> 0
A38: =ROW()-1 -> 37 | B38: 45571 | C38: =TEXT(KDK[[#This Row],[Date]],"dddd") -> Sunday | D38: =WEEKNUM(KDK[[#This Row],[Date]],2) -> 40 | E38: Aakash | F38: =_xlfn.IFNA(0,0) -> 0 | G38: =_xlfn.IFNA(0,0) -> 0 | H38: =KDK[[#This Row],[Brick]]*KDK[[#This Row],[Line]] -> 0 | I38: =IF(MOD(KDK[[#This Row],[Total Brick]],100)>90,KDK[[#This Row],[Total Brick]] - MOD(KDK[[#This Row],[Total Brick]],100) + 100,IF(MOD(KDK[[#This Row],[Total Brick]],100)>40,KDK[[#This Row],[Total Brick]] - MOD(KDK[[#This Row],[Total Brick]],100)+50,KDK[[#This Row],[Total Brick]] - MOD(KDK[[#This Row],[Total Brick]],100))) -> 0 | J38: =_xlfn.IFNA(1.5,0) -> 1.5 | K38: =KDK[[#This Row],[Round Total Brick]]*KDK[[#This Row],[Amount of pre brick]] -> 0
A39: =ROW()-1 -> 38 | B39: 45571 | C39: =TEXT(KDK[[#This Row],[Date]],"dddd") -> Sunday | D39: =WEEKNUM(KDK[[#This Row],[Date]],2) -> 40 | E39: Mahesh | F39: =_xlfn.IFNA(0,0) -> 0 | G39: =_xlfn.IFNA(0,0) -> 0 | H39: =KDK[[#This Row],[Brick]]*KDK[[#This Row],[Line]] -> 0 | I39: =IF(MOD(KDK[[#This Row],[Total Brick]],100)>90,KDK[[#This Row],[Total Brick]] - MOD(KDK[[#This Row],[Total Brick]],100) + 100,IF(MOD(KDK[[#This Row],[Total Brick]],100)>40,KDK[[#This Row],[Total Brick]] - MOD(KDK[[#This Row],[Total Brick]],100)+50,KDK[[#This Row],[Total Brick]] - MOD(KDK[[#This Row],[Total Brick]],100))) -> 0 | J39: =_xlfn.IFNA(1.5,0) -> 1.5 | K39: =KDK[[#This Row],[Round Total Brick]]*KDK[[#This Row],[Amount of pre brick]] -> 0
A40: =ROW()-1 -> 39 | B40: 45571 | C40: =TEXT(KDK[[#This Row],[Date]],"dddd") -> Sunday | D40: =WEEKNUM(KDK[[#This Row],[Date]],2) -> 40 | E40: Ramseesh | F40: =_xlfn.IFNA(0,0) -> 0 | G40: =_xlfn.IFNA(0,0) -> 0 | H40: =KDK[[#This Row],[Brick]]*KDK[[#This Row],[Line]] -> 0 | I40: =IF(MOD(KDK[[#This Row],[Total Brick]],100)>90,KDK[[#This Row],[Total Brick]] - MOD(KDK[[#This Row],[Total Brick]],100) + 100,IF(MOD(KDK[[#This Row],[Total Brick]],100)>40,KDK[[#This Row],[Total Brick]] - MOD(KDK[[#This Row],[Total Brick]],100)+50,KDK[[#This Row],[Total Brick]] - MOD(KDK[[#This Row],[Total Brick]],100))) -> 0 | J40: =_xlfn.IFNA(1.5,0) -> 1.5 | K40: =KDK[[#This Row],[Round Total Brick]]*KDK[[#This Row],[Amount of pre brick]] -> 0
...

Sheet Week Clu
B2: Week | C2: 40
B4: Name | C4: Working days | D4: Total Bricks | E4: Amount
B5: Ramesh | C5: =COUNTIFS(KDK[Name],'Week Clu'!B5,KDK[Line],">0",KDK[No Of Week],$C$2) -> 0 | D5: =SUMIFS(KDK[Round Total Brick],KDK[Name],B5,KDK[No Of Week],$C$2) -> 0 | E5: =SUMIFS(KDK[Total Amount],KDK[Name],Table2[[#This Row],[Name ]],KDK[No Of Week],$C$2) -> 0
B6: Ram | C6: =COUNTIFS(KDK[Name],'Week Clu'!B6,KDK[Line],">0",KDK[No Of Week],$C$2) -> 0 | D6: =SUMIFS(KDK[Round Total Brick],KDK[Name],B6,KDK[No Of Week],$C$2) -> 0 | E6: =SUMIFS(KDK[Total Amount],KDK[Name],Table2[[#This Row],[Name ]],KDK[No Of Week],$C$2) -> 0
B7: Ramseesh | C7: =COUNTIFS(KDK[Name],'Week Clu'!B7,KDK[Line],">0",KDK[No Of Week],$C$2) -> 2 | D7: =SUMIFS(KDK[Round Total Brick],KDK[Name],B7,KDK[No Of Week],$C$2) -> 2100 | E7: =SUMIFS(KDK[Total Amount],KDK[Name],Table2[[#This Row],[Name ]],KDK[No Of Week],$C$2) -> 3150
B8: Settu | C8: =COUNTIFS(KDK[Name],'Week Clu'!B8,KDK[Line],">0",KDK[No Of Week],$C$2) -> 3 | D8: =SUMIFS(KDK[Round Total Brick],KDK[Name],B8,KDK[No Of Week],$C$2) -> 2850 | E8: =SUMIFS(KDK[Total Amount],KDK[Name],Table2[[#This Row],[Name ]],KDK[No Of Week],$C$2) -> 4275
B9: Dhurai | C9: =COUNTIFS(KDK[Name],'Week Clu'!B9,KDK[Line],">0",KDK[No Of Week],$C$2) -> 1 | D9: =SUMIFS(KDK[Round Total Brick],KDK[Name],B9,KDK[No Of Week],$C$2) -> 1250 | E9: =SUMIFS(KDK[Total Amount],KDK[Name],Table2[[#This Row],[Name ]],KDK[No Of Week],$C$2) -> 1875
B10: Aakash | C10: =COUNTIFS(KDK[Name],'Week Clu'!B10,KDK[Line],">0",KDK[No Of Week],$C$2) -> 3 | D10: =SUMIFS(KDK[Round Total Brick],KDK[Name],B10,KDK[No Of Week],$C$2) -> 3250 | E10: =SUMIFS(KDK[Total Amount],KDK[Name],Table2[[#This Row],[Name ]],KDK[No Of Week],$C$2) -> 4875
B11: Mahesh | C11: =COUNTIFS(KDK[Name],'Week Clu'!B11,KDK[Line],">0",KDK[No Of Week],$C$2) -> 0 | D11: =SUMIFS(KDK[Round Total Brick],KDK[Name],B11,KDK[No Of Week],$C$2) -> 0 | E11: =SUMIFS(KDK[Total Amount],KDK[Name],Table2[[#This Row],[Name ]],KDK[No Of Week],$C$2) -> 0
B12: Total | D12: =SUBTOTAL(109,Table2[Total Bricks]) -> 9450 | E12: =SUBTOTAL(109,Table2[Amount]) -> 14175

Sheet Amount
A1: Name | B1: Date | C1: No.Week | D1: Bricks | E1: Amount | F1: Pay | G1: Extra | H1: Balance
A2: Ramseesh | B2: =TODAY() -> 45793 | C2: 40 | D2: =SUMIFS(KDK[Round Total Brick],KDK[Name],Amount!A2,KDK[No Of Week],Table4[[#This Row],[No.Week]]) -> 2100 | E2: =SUMIFS(KDK[Total Amount],KDK[Name],A2,KDK[No Of Week],Table4[[#This Row],[No.Week]]) -> 3150 | F2: =_xlfn.IFNA(0,"") -> 0 | G2: =_xlfn.IFNA(0,"") -> 0 | H2: =_xlfn.IFNA(0,"") -> 0
A3: Ramesh | B3: =TODAY() -> 45793 | C3: 40 | D3: =SUMIFS(KDK[Round Total Brick],KDK[Name],Amount!A3,KDK[No Of Week],Table4[[#This Row],[No.Week]]) -> 0 | E3: =SUMIFS(KDK[Total Amount],KDK[Name],A3,KDK[No Of Week],Table4[[#This Row],[No.Week]]) -> 0 | F3: =_xlfn.IFNA(0,"") -> 0 | G3: =_xlfn.IFNA(0,"") -> 0 | H3: =_xlfn.IFNA(0,"") -> 0
A4: Ram | B4: =TODAY() -> 45793 | C4: 40 | D4: =SUMIFS(KDK[Round Total Brick],KDK[Name],Amount!A4,KDK[No Of Week],Table4[[#This Row],[No.Week]]) -> 0 | E4: =SUMIFS(KDK[Total Amount],KDK[Name],A4,KDK[No Of Week],Table4[[#This Row],[No.Week]]) -> 0 | F4: =_xlfn.IFNA(0,"") -> 0 | G4: =_xlfn.IFNA(0,"") -> 0 | H4: =_xlfn.IFNA(0,"") -> 0
A5: Settu | B5: =TODAY() -> 45793 | C5: 40 | D5: =SUMIFS(KDK[Round Total Brick],KDK[Name],Amount!A5,KDK[No Of Week],Table4[[#This Row],[No.Week]]) -> 2850 | E5: =SUMIFS(KDK[Total Amount],KDK[Name],A5,KDK[No Of Week],Table4[[#This Row],[No.Week]]) -> 4275 | F5: =_xlfn.IFNA(0,"") -> 0 | G5: =_xlfn.IFNA(0,"") -> 0 | H5: =_xlfn.IFNA(0,"") -> 0
A6: Dhurai | B6: =TODAY() -> 45793 | C6: 40 | D6: =SUMIFS(KDK[Round Total Brick],KDK[Name],Amount!A6,KDK[No Of Week],Table4[[#This Row],[No.Week]]) -> 1250 | E6: =SUMIFS(KDK[Total Amount],KDK[Name],A6,KDK[No Of Week],Table4[[#This Row],[No.Week]]) -> 1875 | F6: =_xlfn.IFNA(0,"") -> 0 | G6: =_xlfn.IFNA(0,"") -> 0 | H6: =_xlfn.IFNA(0,"") -> 0
A7: Aakash | B7: =TODAY() -> 45793 | C7: 40 | D7: =SUMIFS(KDK[Round Total Brick],KDK[Name],Amount!A7,KDK[No Of Week],Table4[[#This Row],[No.Week]]) -> 3250 | E7: =SUMIFS(KDK[Total Amount],KDK[Name],A7,KDK[No Of Week],Table4[[#This Row],[No.Week]]) -> 4875 | F7: =_xlfn.IFNA(0,"") -> 0 | G7: =_xlfn.IFNA(0,"") -> 0 | H7: =_xlfn.IFNA(0,"") -> 0
A8: Mahesh | B8: =TODAY() -> 45793 | C8: 41 | D8: =SUMIFS(KDK[Round Total Brick],KDK[Name],Amount!A8,KDK[No Of Week],Table4[[#This Row],[No.Week]]) -> 2150 | E8: =SUMIFS(KDK[Total Amount],KDK[Name],A8,KDK[No Of Week],Table4[[#This Row],[No.Week]]) -> 3225 | F8: =_xlfn.IFNA(0,"") -> 0 | G8: =_xlfn.IFNA(0,"") -> 0 | H8: =_xlfn.IFNA(0,"") -> 0

Sheet Emp
A1: Emp ID | B1: Name | C1: Phone No
A2: 10KDK101 | B2: Ramseesh
A3: 10KDK102 | B3: Ramesh | C3: 8757007762
A4: 10KDK103 | B4: Ram Charan | C4: 6204996078
A5: 10KDK104 | B5: Settu | C5: 7904808713
A6: 10KDK105 | B6: Dhurai
A7: 10KDK106 | B7: Aakash
A8: 10KDK107 | B8: Mahesh
